Workbook

Sheet Analysis Input

Sheet Add Support
A2: Add Support | J2: Active
J3: Passive
A5: Toe Block Support
A6: Nature of Force Application | B6: 2
A7: Magnitude, T = | C7: kN
A8: Orientation, i = | C8: °
A9: Optimum Orientation (against sliding) = | C9: ° (Based on Mean Block Geometry)
A10: Optimum Orientation (against toppling) = | C10: ° (Based on Mean Block Geometry)
A12: Bolt Blocks Together
A14: Effective Width = | C14: x Actual Block Width | G14: Example of Toe Block Support

Sheet Results
A2: Results
H3: Summary of Kinematic Probabilities | O3: Distribution of the Factor of Safety
B5: Kinematic Probability of Block Toppling Failure (Pf Kinematic) | F5: 0.615 | I5: Kinematic Mode | L5: Number of Trials | M5: Kinematic Probability
B7: Kinetic Probability of Block Toppling Failure (Pf Kinetic | Kinematic) | F7: 0.23577236 | I7: Block Toppling | L7: 615 | M7: 0.615
I8: Sliding on Set A Only | L8: 28 | M8: 0.028
B9: Total Probability of Block Toppling Failure (Pf Kinematic) x (Pf Kinetic | Kinematic) | F9: 0.145 | I9: Toppling on Set B Only | L9: 97 | M9: 0.097
I10: Sliding and Toppling | L10: 144 | M10: 0.144
B11: Mean FS | Kinematically Feasible | F11: 1.1822268 | I11: No Kinematic Failure | L11: 116 | M11: 0.116
B12: Median FS | Kinematically Feasible | F12: 1.1452872 | I12: Total | L12: 1000 | M12: 1
H14: Summary of Kinetic Probabilities
I16: Critical Failure Mode for Toe Block(s) | J16: Number of Trials | M16: Pf kinetic
J17: Total | K17: Stable | L17: Unstable
I18: Sliding | J18: 615 | K18: 470 | L18: 145 | M18: 0.23577236
I19: Toppling | J19: 0 | K19: 0 | L19: 0 | M19: 0
I20: Total | J20: 615 | K20: 470 | L20: 145 | M20: 0.23577236
H22: Summary of Support
I24: Support | J24: Yes/No | K24: Magnitude, T (kN) | L24: Orientation, i (°) | M24: Active/ Passive?
I25: Toe Block | J25: No | K25: - | L25: - | M25: -
I26: Blocks Bolted Together | J26: No | K26: - | L26: - | M26: -
A106: 100
A107: 1
M265: -
A1006: 1000
A1007: 1
A5005: 1
A5006: 4999
A5007: 0.9998

Sheet Frequency
A1: Bin | B1: Frequency (Sliding) | C1: Probability Density | D1: Frequency (Topple) | E1: Probability Density | F1: Cumulative (Frequency) | G1: Cumlative (Sliding Frequency ) | H1: Cumulative (Toppling Toppling ) | I1: Cumulative Probability (Sliding) | J1: Cumulative Probability (Toppling) | K1: Cumulative Probability (Total)
B2: {=FREQUENCY('Analysis Details 2'!Z3:Z25000,Frequency!A2:A25000)} -> 0 | C2: =IF(A2="","",B2/(SUM(Results!$J$18:$J$19))) | D2: {=FREQUENCY('Analysis Details 2'!AA3:AA25000,Frequency!A2:A25000)} -> 0 | E2: =IF(A2="","",D2/SUM(Results!$J$18:$J$19))
A3: 0.1 | B3: 0 | C3: =IF(A3="","",B3/(SUM(Results!$J$18:$J$19))) -> 0 | D3: 0 | E3: =IF(A3="","",D3/SUM(Results!$J$18:$J$19)) -> 0 | F3: =IF(A3="","",(B3+D3+F2)/Results!L$12) -> 0 | G3: =IF(A3="","",(B3+G2)) -> 0 | H3: =IF(A3="","",(D3+H2)) -> 0 | I3: =IF(A3="","",G3/Results!$J$18) -> 0 | J3: =IF(A3="","",H3/Results!$J$19) -> #DIV/0! | K3: =IF(A3="","",F3/Results!$J$20) -> 0
A4: 0.2 | B4: 0 | C4: =IF(A4="","",B4/(SUM(Results!$J$18:$J$19))) -> 0 | D4: 0 | E4: =IF(A4="","",D4/SUM(Results!$J$18:$J$19)) -> 0 | F4: =IF(A4="","",(B4+D4+F3)) -> 0 | G4: =IF(A4="","",(B4+G3)) -> 0 | H4: =IF(A4="","",(D4+H3)) -> 0 | I4: =IF(A4="","",G4/Results!$J$18) -> 0 | J4: =IF(A4="","",H4/Results!$J$19) -> #DIV/0! | K4: =IF(A4="","",F4/Results!$J$20) -> 0
A5: 0.3 | B5: 0 | C5: =IF(A5="","",B5/(SUM(Results!$J$18:$J$19))) -> 0 | D5: 0 | E5: =IF(A5="","",D5/SUM(Results!$J$18:$J$19)) -> 0 | F5: =IF(A5="","",(B5+D5+F4)) -> 0 | G5: =IF(A5="","",(B5+G4)) -> 0 | H5: =IF(A5="","",(D5+H4)) -> 0 | I5: =IF(A5="","",G5/Results!$J$18) -> 0 | J5: =IF(A5="","",H5/Results!$J$19) -> #DIV/0! | K5: =IF(A5="","",F5/Results!$J$20) -> 0
A6: 0.4 | B6: 0 | C6: =IF(A6="","",B6/(SUM(Results!$J$18:$J$19))) -> 0 | D6: 0 | E6: =IF(A6="","",D6/SUM(Results!$J$18:$J$19)) -> 0 | F6: =IF(A6="","",(B6+D6+F5)) -> 0 | G6: =IF(A6="","",(B6+G5)) -> 0 | H6: =IF(A6="","",(D6+H5)) -> 0 | I6: =IF(A6="","",G6/Results!$J$18) -> 0 | J6: =IF(A6="","",H6/Results!$J$19) -> #DIV/0! | K6: =IF(A6="","",F6/Results!$J$20) -> 0
A7: 0.5 | B7: 6 | C7: =IF(A7="","",B7/(SUM(Results!$J$18:$J$19))) -> 0.0097560976 | D7: 0 | E7: =IF(A7="","",D7/SUM(Results!$J$18:$J$19)) -> 0 | F7: =IF(A7="","",(B7+D7+F6)) -> 6 | G7: =IF(A7="","",(B7+G6)) -> 6 | H7: =IF(A7="","",(D7+H6)) -> 0 | I7: =IF(A7="","",G7/Results!$J$18) -> 0.0097560976 | J7: =IF(A7="","",H7/Results!$J$19) -> #DIV/0! | K7: =IF(A7="","",F7/Results!$J$20) -> 0.0097560976
A8: 0.6 | B8: 22 | C8: =IF(A8="","",B8/(SUM(Results!$J$18:$J$19))) -> 0.035772358 | D8: 0 | E8: =IF(A8="","",D8/SUM(Results!$J$18:$J$19)) -> 0 | F8: =IF(A8="","",(B8+D8+F7)) -> 28 | G8: =IF(A8="","",(B8+G7)) -> 28 | H8: =IF(A8="","",(D8+H7)) -> 0 | I8: =IF(A8="","",G8/Results!$J$18) -> 0.045528455 | J8: =IF(A8="","",H8/Results!$J$19) -> #DIV/0! | K8: =IF(A8="","",F8/Results!$J$20) -> 0.045528455
A9: 0.7 | B9: 48 | C9: =IF(A9="","",B9/(SUM(Results!$J$18:$J$19))) -> 0.07804878 | D9: 0 | E9: =IF(A9="","",D9/SUM(Results!$J$18:$J$19)) -> 0 | F9: =IF(A9="","",(B9+D9+F8)) -> 76 | G9: =IF(A9="","",(B9+G8)) -> 76 | H9: =IF(A9="","",(D9+H8)) -> 0 | I9: =IF(A9="","",G9/Results!$J$18) -> 0.12357724 | J9: =IF(A9="","",H9/Results!$J$19) -> #DIV/0! | K9: =IF(A9="","",F9/Results!$J$20) -> 0.12357724
A10: 0.8 | B10: 37 | C10: =IF(A10="","",B10/(SUM(Results!$J$18:$J$19))) -> 0.060162602 | D10: 0 | E10: =IF(A10="","",D10/SUM(Results!$J$18:$J$19)) -> 0 | F10: =IF(A10="","",(B10+D10+F9)) -> 113 | G10: =IF(A10="","",(B10+G9)) -> 113 | H10: =IF(A10="","",(D10+H9)) -> 0 | I10: =IF(A10="","",G10/Results!$J$18) -> 0.18373984 | J10: =IF(A10="","",H10/Results!$J$19) -> #DIV/0! | K10: =IF(A10="","",F10/Results!$J$20) -> 0.18373984
A11: 0.9 | B11: 32 | C11: =IF(A11="","",B11/(SUM(Results!$J$18:$J$19))) -> 0.05203252 | D11: 0 | E11: =IF(A11="","",D11/SUM(Results!$J$18:$J$19)) -> 0 | F11: =IF(A11="","",(B11+D11+F10)) -> 145 | G11: =IF(A11="","",(B11+G10)) -> 145 | H11: =IF(A11="","",(D11+H10)) -> 0 | I11: =IF(A11="","",G11/Results!$J$18) -> 0.23577236 | J11: =IF(A11="","",H11/Results!$J$19) -> #DIV/0! | K11: =IF(A11="","",F11/Results!$J$20) -> 0.23577236
A12: 1 | B12: 108 | C12: =IF(A12="","",B12/(SUM(Results!$J$18:$J$19))) -> 0.17560976 | D12: 0 | E12: =IF(A12="","",D12/SUM(Results!$J$18:$J$19)) -> 0 | F12: =IF(A12="","",(B12+D12+F11)) -> 253 | G12: =IF(A12="","",(B12+G11)) -> 253 | H12: =IF(A12="","",(D12+H11)) -> 0 | I12: =IF(A12="","",G12/Results!$J$18) -> 0.41138211 | J12: =IF(A12="","",H12/Results!$J$19) -> #DIV/0! | K12: =IF(A12="","",F12/Results!$J$20) -> 0.41138211
A13: 1.1 | B13: 90 | C13: =IF(A13="","",B13/(SUM(Results!$J$18:$J$19))) -> 0.14634146 | D13: 0 | E13: =IF(A13="","",D13/SUM(Results!$J$18:$J$19)) -> 0 | F13: =IF(A13="","",(B13+D13+F12)) -> 343 | G13: =IF(A13="","",(B13+G12)) -> 343 | H13: =IF(A13="","",(D13+H12)) -> 0 | I13: =IF(A13="","",G13/Results!$J$18) -> 0.55772358 | J13: =IF(A13="","",H13/Results!$J$19) -> #DIV/0! | K13: =IF(A13="","",F13/Results!$J$20) -> 0.55772358
A14: 1.2 | B14: 93 | C14: =IF(A14="","",B14/(SUM(Results!$J$18:$J$19))) -> 0.15121951 | D14: 0 | E14: =IF(A14="","",D14/SUM(Results!$J$18:$J$19)) -> 0 | F14: =IF(A14="","",(B14+D14+F13)) -> 436 | G14: =IF(A14="","",(B14+G13)) -> 436 | H14: =IF(A14="","",(D14+H13)) -> 0 | I14: =IF(A14="","",G14/Results!$J$18) -> 0.70894309 | J14: =IF(A14="","",H14/Results!$J$19) -> #DIV/0! | K14: =IF(A14="","",F14/Results!$J$20) -> 0.70894309
A15: 1.3 | B15: 54 | C15: =IF(A15="","",B15/(SUM(Results!$J$18:$J$19))) -> 0.087804878 | D15: 0 | E15: =IF(A15="","",D15/SUM(Results!$J$18:$J$19)) -> 0 | F15: =IF(A15="","",(B15+D15+F14)) -> 490 | G15: =IF(A15="","",(B15+G14)) -> 490 | H15: =IF(A15="","",(D15+H14)) -> 0 | I15: =IF(A15="","",G15/Results!$J$18) -> 0.79674797 | J15: =IF(A15="","",H15/Results!$J$19) -> #DIV/0! | K15: =IF(A15="","",F15/Results!$J$20) -> 0.79674797
... A31: 2.9 | B31: 0 | C31: =IF(A31="","",B31/(SUM(Results!$J$18:$J$19))) -> 0 | D31: 0 | E31: =IF(A31="","",D31/SUM(Results!$J$18:$J$19)) -> 0 | F31: =IF(A31="","",(B31+D31+F30)) -> 615 | G31: =IF(A31="","",(B31+G30)) -> 615 | H31: =IF(A31="","",(D31+H30)) -> 0 | I31: =IF(A31="","",G31/Results!$J$18) -> 1 | J31: =IF(A31="","",H31/Results!$J$19) -> #DIV/0! | K31: =IF(A31="","",F31/Results!$J$20) -> 1
B32: #N/A | C32: =IF(A32="","",B32/(SUM(Results!$J$18:$J$19))) | D32: #N/A | E32: =IF(A32="","",D32/SUM(Results!$J$18:$J$19)) | F32: =IF(A32="","",(B32+D32+F31)) | G32: =IF(A32="","",(B32+G31)) | H32: =IF(A32="","",(D32+H31)) | I32: =IF(A32="","",G32/Results!$J$18) | J32: =IF(A32="","",H32/Results!$J$19) | K32: =IF(A32="","",F32/Results!$J$20)
B33: #N/A | C33: =IF(A33="","",B33/(SUM(Results!$J$18:$J$19))) | D33: #N/A | E33: =IF(A33="","",D33/SUM(Results!$J$18:$J$19)) | F33: =IF(A33="","",(B33+D33+F32)) | G33: =IF(A33="","",(B33+G32)) | H33: =IF(A33="","",(D33+H32)) | I33: =IF(A33="","",G33/Results!$J$18) | J33: =IF(A33="","",H33/Results!$J$19) | K33: =IF(A33="","",F33/Results!$J$20)
B34: #N/A | C34: =IF(A34="","",B34/(SUM(Results!$J$18:$J$19))) | D34: #N/A | E34: =IF(A34="","",D34/SUM(Results!$J$18:$J$19)) | F34: =IF(A34="","",(B34+D34+F33)) | G34: =IF(A34="","",(B34+G33)) | H34: =IF(A34="","",(D34+H33)) | I34: =IF(A34="","",G34/Results!$J$18) | J34: =IF(A34="","",H34/Results!$J$19) | K34: =IF(A34="","",F34/Results!$J$20)
B35: #N/A | C35: =IF(A35="","",B35/(SUM(Results!$J$18:$J$19))) | D35: #N/A | E35: =IF(A35="","",D35/SUM(Results!$J$18:$J$19)) | F35: =IF(A35="","",(B35+D35+F34)) | G35: =IF(A35="","",(B35+G34)) | H35: =IF(A35="","",(D35+H34)) | I35: =IF(A35="","",G35/Results!$J$18) | J35: =IF(A35="","",H35/Results!$J$19) | K35: =IF(A35="","",F35/Results!$J$20)
B36: #N/A | C36: =IF(A36="","",B36/(SUM(Results!$J$18:$J$19))) | D36: #N/A | E36: =IF(A36="","",D36/SUM(Results!$J$18:$J$19)) | F36: =IF(A36="","",(B36+D36+F35)) | G36: =IF(A36="","",(B36+G35)) | H36: =IF(A36="","",(D36+H35)) | I36: =IF(A36="","",G36/Results!$J$18) | J36: =IF(A36="","",H36/Results!$J$19) | K36: =IF(A36="","",F36/Results!$J$20)
B37: #N/A | C37: =IF(A37="","",B37/(SUM(Results!$J$18:$J$19))) | D37: #N/A | E37: =IF(A37="","",D37/SUM(Results!$J$18:$J$19)) | F37: =IF(A37="","",(B37+D37+F36)) | G37: =IF(A37="","",(B37+G36)) | H37: =IF(A37="","",(D37+H36)) | I37: =IF(A37="","",G37/Results!$J$18) | J37: =IF(A37="","",H37/Results!$J$19) | K37: =IF(A37="","",F37/Results!$J$20)
B38: #N/A | C38: =IF(A38="","",B38/(SUM(Results!$J$18:$J$19))) | D38: #N/A | E38: =IF(A38="","",D38/SUM(Results!$J$18:$J$19)) | F38: =IF(A38="","",(B38+D38+F37)) | G38: =IF(A38="","",(B38+G37)) | H38: =IF(A38="","",(D38+H37)) | I38: =IF(A38="","",G38/Results!$J$18) | J38: =IF(A38="","",H38/Results!$J$19) | K38: =IF(A38="","",F38/Results!$J$20)
B39: #N/A | C39: =IF(A39="","",B39/(SUM(Results!$J$18:$J$19))) | D39: #N/A | E39: =IF(A39="","",D39/SUM(Results!$J$18:$J$19)) | F39: =IF(A39="","",(B39+D39+F38)) | G39: =IF(A39="","",(B39+G38)) | H39: =IF(A39="","",(D39+H38)) | I39: =IF(A39="","",G39/Results!$J$18) | J39: =IF(A39="","",H39/Results!$J$19) | K39: =IF(A39="","",F39/Results!$J$20)
B40: #N/A | C40: =IF(A40="","",B40/(SUM(Results!$J$18:$J$19))) | D40: #N/A | E40: =IF(A40="","",D40/SUM(Results!$J$18:$J$19)) | F40: =IF(A40="","",(B40+D40+F39)) | G40: =IF(A40="","",(B40+G39)) | H40: =IF(A40="","",(D40+H39)) | I40: =IF(A40="","",G40/Results!$J$18) | J40: =IF(A40="","",H40/Results!$J$19) | K40: =IF(A40="","",F40/Results!$J$20)
B41: #N/A | C41: =IF(A41="","",B41/(SUM(Results!$J$18:$J$19))) | D41: #N/A | E41: =IF(A41="","",D41/SUM(Results!$J$18:$J$19)) | F41: =IF(A41="","",(B41+D41+F40)) | G41: =IF(A41="","",(B41+G40)) | H41: =IF(A41="","",(D41+H40)) | I41: =IF(A41="","",G41/Results!$J$18) | J41: =IF(A41="","",H41/Results!$J$19) | K41: =IF(A41="","",F41/Results!$J$20)
B42: #N/A | C42: =IF(A42="","",B42/(SUM(Results!$J$18:$J$19))) | D42: #N/A | E42: =IF(A42="","",D42/SUM(Results!$J$18:$J$19)) | F42: =IF(A42="","",(B42+D42+F41)) | G42: =IF(A42="","",(B42+G41)) | H42: =IF(A42="","",(D42+H41)) | I42: =IF(A42="","",G42/Results!$J$18) | J42: =IF(A42="","",H42/Results!$J$19) | K42: =IF(A42="","",F42/Results!$J$20)
B43: #N/A | C43: =IF(A43="","",B43/(SUM(Results!$J$18:$J$19))) | D43: #N/A | E43: =IF(A43="","",D43/SUM(Results!$J$18:$J$19)) | F43: =IF(A43="","",(B43+D43+F42)) | G43: =IF(A43="","",(B43+G42)) | H43: =IF(A43="","",(D43+H42)) | I43: =IF(A43="","",G43/Results!$J$18) | J43: =IF(A43="","",H43/Results!$J$19) | K43: =IF(A43="","",F43/Results!$J$20)
... B1000: #N/A | C1000: =IF(A1000="","",B1000/(SUM(Results!$J$18:$J$19))) | D1000: #N/A | E1000: =IF(A1000="","",D1000/SUM(Results!$J$18:$J$19)) | F1000: =IF(A1000="","",(B1000+D1000+F999)) | G1000: =IF(A1000="","",(B1000+G999)) | H1000: =IF(A1000="","",(D1000+H999)) | I1000: =IF(A1000="","",G1000/Results!$J$18) | J1000: =IF(A1000="","",H1000/Results!$J$19) | K1000: =IF(A1000="","",F1000/Results!$J$20)

Sheet Analysis Details 1
A1: Coordinates Defining Mean Geometry
A2: Total Blocks = | B2: 8 | G2: Pore Pressure = | H2: 0.1
A4: Overall Slope Geometry | B4: x | C4: y
A5: Left Limit of Slope | B5: -10 | C5: 0
A6: Slope Toe | B6: 0 | C6: 0
A7: Slope Crest | B7: 5.4595535 | C7: 15
A8: Right Limit of Slope | B8: 27.164084 | C8: 15.94764
A9: Block | B9: x | C9: y | F9: water level | G9: x | H9: y
A10: Block 1 | B10: 0 | C10: 0 | F10: U/S | G10: 0 | H10: 0
B11: 0 | C11: 0 | F11: D/S | G11: 2.1422484 | H11: 1.4860828
B12: 2.2268488 | C12: 1.2296653
B13: 1.380845 | C13: 3.7938405
A14: Block 2 | B14: 1.380845 | C14: 3.7938405 | F14: U/S | G14: 2.1422484 | H14: 1.4860828
B15: 1.987742 | C15: 1.9543803 | F15: D/S | G15: 4.0693007 | H15: 3.6244092
B16: 4.2145908 | C16: 3.1840456
B17: 2.7616901 | C17: 7.5876811
A18: Block 3 | B18: 2.7616901 | C18: 7.5876811 | F18: U/S | G18: 4.0693007 | H18: 3.6244092
B19: 3.975484 | C19: 3.9087607 | F19: D/S | G19: 5.996353 | H19: 5.7627355
B20: 6.2023328 | C20: 5.138426
B21: 4.1425351 | C21: 11.381522
A22: Block 4 | B22: 4.1425351 | C22: 11.381522 | F22: U/S | G22: 5.996353 | H22: 5.7627355
B23: 5.9632261 | C23: 5.863141 | F23: D/S | G23: 7.9290183 | H23: 7.8840494
B24: 8.1900748 | C24: 7.0928063
B25: 5.5795098 | C25: 15.005237
A26: Block 5 | B26: 5.5795098 | C26: 15.005237 | F26: U/S | G26: 7.9290183 | H26: 7.8840494
B27: 7.9509681 | C27: 7.8175213 | F27: D/S | G27: 9.9775032 | H27: 9.6543225
B28: 10.177817 | C28: 9.0471866
B29: 8.1746808 | C29: 15.118545
A30: Block 6 | B30: 8.1746808 | C30: 15.118545 | F30: U/S | G30: 9.9775032 | H30: 9.6543225
B31: 9.9387101 | C31: 9.7719016 | F31: D/S | G31: 12.025988 | H31: 11.424596
B32: 12.165559 | C32: 11.001567
B33: 10.769852 | C33: 15.231853
A34: Block 7 | B34: 10.769852 | C34: 15.231853 | F34: U/S | G34: 12.025988 | H34: 11.424596
B35: 11.926452 | C35: 11.726282 | F35: D/S | G35: 14.074473 | H35: 13.194869
B36: 14.153301 | C36: 12.955947
B37: 13.365023 | C37: 15.34516
A38: Block 8 | B38: 13.365023 | C38: 15.34516 | F38: U/S | G38: 14.074473 | H38: 13.194869
B39: 13.914194 | C39: 13.680662 | F39: D/S | G39: 16.122958 | H39: 14.965142
B40: 16.141043 | C40: 14.910328 | G40: 27.164084 | H40: 15.94764
B41: 15.960194 | C41: 15.458468

Sheet Analysis Details 2
A1: Details of Toe Block Stability | H1: Summary of Kinematic Stability | L1: Summary of Kinetic Stability
A2: Trial | B2: ya (°) | C2: aa (°) | D2: yb (°) | E2: ab (°) | F2: fa (°) | G2: fb (°) | H2: Block Toppling | I2: Sliding on Set A Only | J2: Toppling on Set B Only | K2: Sliding and Toppling | L2: Total Number of Blocks, n | M2: Number of Stable Blocks Above Toe Block | N2: Failure Mode of n-1 Block | O2: Pn (kN) | P2: Rn (kN) | Q2: Sn (kN) | R2: Resisiting Force (kN) | S2: Driving Force (kN) | T2: Factor of Safety (sliding) | U2: Resisiting Moment (kN-m) | V2: Driving Moment (kN-m) | W2: Factor of Safety (toppling) | X2: Critical Failure Mode of Toe Block(s) | Y2: Factor of Safety | Z2: sliding | AA2: toppling | AB2: Factor of safety
A3: 1 | B3: 21 | C3: 42 | D3: 68 | E3: 222 | F3: 33 | G3: 33 | H3: TRUE | I3: FALSE | J3: FALSE | K3: FALSE | L3: 11 | M3: 0 | N3: Toppling | O3: 84.863864 | P3: 139.5419 | Q3: 118.56006 | R3: 91.9202 | S3: 118.56006 | T3: 0.77530492 | U3: 252.30668 | V3: 245.86442 | W3: 1.0262025 | X3: Sliding | Y3: 0.77530492 | Z3: =IF(X3="-","",IF(X3="Sliding",Y3,"")) -> 0.77530492 | AA3: =IF(X3="-","",IF(X3="Toppling",Y3,"")) | AB3: =IF(X3="invalid","Invalid",IF(Z3="",AA3,Z3)) -> 0.77530492
A4: 2 | B4: 21 | C4: 63 | D4: 76 | E4: 237 | F4: 36 | G4: 31 | H4: TRUE | I4: FALSE | J4: FALSE | K4: FALSE | L4: 9 | M4: 3 | N4: Stable | O4: 0 | P4: 130.53316 | Q4: 53.089096 | R4: 1062.5784 | S4: 589.59131 | T4: 1.8022287 | U4: 216.54589 | V4: 10.716589 | W4: - | X4: Sliding | Y4: 1.8022287 | Z4: =IF(X4="-","",IF(X4="Sliding",Y4,"")) -> 1.8022287 | AA4: =IF(X4="-","",IF(X4="Toppling",Y4,"")) | AB4: =IF(X4="invalid","Invalid",IF(Z4="",AA4,Z4)) -> 1.8022287
A5: 3 | B5: 26 | C5: 60 | D5: 73 | E5: 217 | F5: 37 | G5: 35 | H5: TRUE | I5: FALSE | J5: FALSE | K5: FALSE | L5: 9 | M5: 4 | N5: Stable | O5: 0 | P5: 51.398321 | Q5: 25.815578 | R5: 1062.4343 | S5: 706.54656 | T5: 1.5037003 | U5: 57.778126 | V5: 2.965539 | W5: - | X5: Sliding | Y5: 1.5037003 | Z5: =IF(X5="-","",IF(X5="Sliding",Y5,"")) -> 1.5037003 | AA5: =IF(X5="-","",IF(X5="Toppling",Y5,"")) | AB5: =IF(X5="invalid","Invalid",IF(Z5="",AA5,Z5)) -> 1.5037003
A6: 4 | B6: 34 | C6: 68 | D6: 62 | E6: 218 | F6: 36 | G6: 36 | H6: TRUE | I6: FALSE | J6: FALSE | K6: FALSE | L6: 7 | M6: 0 | N6: Sliding | O6: 43.702671 | P6: 75.69033 | Q6: 82.05408 | R6: 54.983474 | S6: 82.05408 | T6: 0.67008823 | U6: 143.39066 | V6: 99.680447 | W6: 1.4385034 | X6: Sliding | Y6: 0.67008823 | Z6: =IF(X6="-","",IF(X6="Sliding",Y6,"")) -> 0.67008823 | AA6: =IF(X6="-","",IF(X6="Toppling",Y6,"")) | AB6: =IF(X6="invalid","Invalid",IF(Z6="",AA6,Z6)) -> 0.67008823
A7: 5 | B7: 28 | C7: 52 | D7: 77 | E7: 214 | F7: 32 | G7: 32 | H7: FALSE | I7: FALSE | J7: FALSE | K7: FALSE | L7: - | M7: - | N7: - | O7: - | P7: - | Q7: - | R7: - | S7: - | T7: - | U7: - | V7: - | W7: - | X7: - | Y7: - | Z7: =IF(X7="-","",IF(X7="Sliding",Y7,"")) | AA7: =IF(X7="-","",IF(X7="Toppling",Y7,"")) | AB7: =IF(X7="invalid","Invalid",IF(Z7="",AA7,Z7))
A8: 6 | B8: 25 | C8: 35 | D8: 70 | E8: 232 | F8: 40 | G8: 36 | H8: FALSE | I8: FALSE | J8: TRUE | K8: FALSE | L8: - | M8: - | N8: - | O8: - | P8: - | Q8: - | R8: - | S8: - | T8: - | U8: - | V8: - | W8: - | X8: - | Y8: - | Z8: =IF(X8="-","",IF(X8="Sliding",Y8,"")) | AA8: =IF(X8="-","",IF(X8="Toppling",Y8,"")) | AB8: =IF(X8="invalid","Invalid",IF(Z8="",AA8,Z8))
A9: 7 | B9: 31 | C9: 43 | D9: 72 | E9: 214 | F9: 33 | G9: 30 | H9: FALSE | I9: FALSE | J9: FALSE | K9: FALSE | L9: - | M9: - | N9: - | O9: - | P9: - | Q9: - | R9: - | S9: - | T9: - | U9: - | V9: - | W9: - | X9: - | Y9: - | Z9: =IF(X9="-","",IF(X9="Sliding",Y9,"")) | AA9: =IF(X9="-","",IF(X9="Toppling",Y9,"")) | AB9: =IF(X9="invalid","Invalid",IF(Z9="",AA9,Z9))
A10: 8 | B10: 25 | C10: 42 | D10: 51 | E10: 205 | F10: 30 | G10: 33 | H10: FALSE | I10: FALSE | J10: FALSE | K10: FALSE | L10: - | M10: - | N10: - | O10: - | P10: - | Q10: - | R10: - | S10: - | T10: - | U10: - | V10: - | W10: - | X10: - | Y10: - | Z10: =IF(X10="-","",IF(X10="Sliding",Y10,"")) | AA10: =IF(X10="-","",IF(X10="Toppling",Y10,"")) | AB10: =IF(X10="invalid","Invalid",IF(Z10="",AA10,Z10))
A11: 9 | B11: 38 | C11: 54 | D11: 68 | E11: 223 | F11: 35 | G11: 33 | H11: FALSE | I11: FALSE | J11: FALSE | K11: TRUE | L11: - | M11: - | N11: - | O11: - | P11: - | Q11: - | R11: - | S11: - | T11: - | U11: - | V11: - | W11: - | X11: - | Y11: - | Z11: =IF(X11="-","",IF(X11="Sliding",Y11,"")) | AA11: =IF(X11="-","",IF(X11="Toppling",Y11,"")) | AB11: =IF(X11="invalid","Invalid",IF(Z11="",AA11,Z11))
A12: 10 | B12: 26 | C12: 65 | D12: 70 | E12: 226 | F12: 37 | G12: 29 | H12: TRUE | I12: FALSE | J12: FALSE | K12: FALSE | L12: 8 | M12: 7 | N12: Stable | O12: 0 | P12: 44.365966 | Q12: 22.299362 | R12: 1494.0976 | S12: 957.688 | T12: 1.5601089 | U12: 46.564429 | V12: 2.3695879 | W12: - | X12: Sliding | Y12: 1.5601089 | Z12: =IF(X12="-","",IF(X12="Sliding",Y12,"")) -> 1.5601089 | AA12: =IF(X12="-","",IF(X12="Toppling",Y12,"")) | AB12: =IF(X12="invalid","Invalid",IF(Z12="",AA12,Z12)) -> 1.5601089
A13: 11 | B13: 27 | C13: 49 | D13: 67 | E13: 219 | F13: 34 | G13: 35 | H13: TRUE | I13: FALSE | J13: FALSE | K13: FALSE | L13: 8 | M13: 1 | N13: Stable | O13: 0 | P13: 54.844754 | Q13: 29.649451 | R13: 150.13934 | S13: 126.70273 | T13: 1.1849732 | U13: 66.344005 | V13: 3.3815702 | W13: - | X13: Sliding | Y13: 1.1849732 | Z13: =IF(X13="-","",IF(X13="Sliding",Y13,"")) -> 1.1849732 | AA13: =IF(X13="-","",IF(X13="Toppling",Y13,"")) | AB13: =IF(X13="invalid","Invalid",IF(Z13="",AA13,Z13)) -> 1.1849732
A14: 12 | B14: 28 | C14: 51 | D14: 64 | E14: 232 | F14: 36 | G14: 29 | H14: TRUE | I14: FALSE | J14: FALSE | K14: FALSE | L14: 8 | M14: 0 | N14: Toppling | O14: 45.059313 | P14: 80.648015 | Q14: 77.514334 | R14: 59.26327 | S14: 77.514334 | T14: 0.76454595 | U14: 130.32369 | V14: 107.11274 | W14: 1.2166964 | X14: Sliding | Y14: 0.76454595 | Z14: =IF(X14="-","",IF(X14="Sliding",Y14,"")) -> 0.76454595 | AA14: =IF(X14="-","",IF(X14="Toppling",Y14,"")) | AB14: =IF(X14="invalid","Invalid",IF(Z14="",AA14,Z14)) -> 0.76454595
A15: 13 | B15: 27 | C15: 61 | D15: 71 | E15: 233 | F15: 36 | G15: 36 | H15: TRUE | I15: FALSE | J15: FALSE | K15: FALSE | L15: 7 | M15: 6 | N15: Stable | O15: 0 | P15: 64.921933 | Q15: 34.81802 | R15: 1166.9915 | S15: 838.11181 | T15: 1.3924055 | U15: 84.600356 | V15: 4.3717828 | W15: - | X15: Sliding | Y15: 1.3924055 | Z15: =IF(X15="-","",IF(X15="Sliding",Y15,"")) -> 1.3924055 | AA15: =IF(X15="-","",IF(X15="Toppling",Y15,"")) | AB15: =IF(X15="invalid","Invalid",IF(Z15="",AA15,Z15)) -> 1.3924055
A16: 14 | B16: 34 | C16: 34 | D16: 64 | E16: 223 | F16: 39 | G16: 38 | H16: FALSE | I16: FALSE | J16: TRUE | K16: FALSE | L16: - | M16: - | N16: - | O16: - | P16: - | Q16: - | R16: - | S16: - | T16: - | U16: - | V16: - | W16: - | X16: - | Y16: - | Z16: =IF(X16="-","",IF(X16="Sliding",Y16,"")) | AA16: =IF(X16="-","",IF(X16="Toppling",Y16,"")) | AB16: =IF(X16="invalid","Invalid",IF(Z16="",AA16,Z16))
A17: 15 | B17: 30 | C17: 41 | D17: 59 | E17: 210 | F17: 32 | G17: 35 | H17: FALSE | I17: FALSE | J17: FALSE | K17: FALSE | L17: - | M17: - | N17: - | O17: - | P17: - | Q17: - | R17: - | S17: - | T17: - | U17: - | V17: - | W17: - | X17: - | Y17: - | Z17: =IF(X17="-","",IF(X17="Sliding",Y17,"")) | AA17: =IF(X17="-","",IF(X17="Toppling",Y17,"")) | AB17: =IF(X17="invalid","Invalid",IF(Z17="",AA17,Z17))
A18: 16 | B18: 27 | C18: 44 | D18: 81 | E18: 249 | F18: 38 | G18: 38 | H18: TRUE | I18: FALSE | J18: FALSE | K18: FALSE | L18: 8 | M18: 7 | N18: Stable | O18: 0 | P18: 115.28163 | Q18: 61.781329 | R18: 1894.2525 | S18: 1265.7134 | T18: 1.4965888 | U18: 196.53303 | V18: 10.556263 | W18: - | X18: Sliding | Y18: 1.4965888 | Z18: =IF(X18="-","",IF(X18="Sliding",Y18,"")) -> 1.4965888 | AA18: =IF(X18="-","",IF(X18="Toppling",Y18,"")) | AB18: =IF(X18="invalid","Invalid",IF(Z18="",AA18,Z18)) -> 1.4965888
A19: 17 | B19: 29 | C19: 45 | D19: 70 | E19: 230 | F19: 32 | G19: 31 | H19: TRUE | I19: FALSE | J19: FALSE | K19: FALSE | L19: 8 | M19: 3 | N19: Stable | O19: 0 | P19: 82.947535 | Q19: 47.881254 | R19: 638.33008 | S19: 592.56348 | T19: 1.0772349 | U19: 126.40307 | V19: 6.6390989 | W19: - | X19: Sliding | Y19: 1.0772349 | Z19: =IF(X19="-","",IF(X19="Sliding",Y19,"")) -> 1.0772349 | AA19: =IF(X19="-","",IF(X19="Toppling",Y19,"")) | AB19: =IF(X19="invalid","Invalid",IF(Z19="",AA19,Z19)) -> 1.0772349
A20: 18 | B20: 31 | C20: 42 | D20: 71 | E20: 226 | F20: 37 | G20: 37 | H20: TRUE | I20: FALSE | J20: FALSE | K20: FALSE | L20: 8 | M20: 1 | N20: Stable | O20: 0 | P20: 120.08316 | Q20: 74.627262 | R20: 225.42181 | S20: 185.16343 | T20: 1.2174208 | U20: 228.01052 | V20: 12.310033 | W20: - | X20: Sliding | Y20: 1.2174208 | Z20: =IF(X20="-","",IF(X20="Sliding",Y20,"")) -> 1.2174208 | AA20: =IF(X20="-","",IF(X20="Toppling",Y20,"")) | AB20: =IF(X20="invalid","Invalid",IF(Z20="",AA20,Z20)) -> 1.2174208
A21: 19 | B21: 23 | C21: 39 | D21: 87 | E21: 213 | F21: 37 | G21: 37 | H21: FALSE | I21: FALSE | J21: FALSE | K21: FALSE | L21: - | M21: - | N21: - | O21: - | P21: - | Q21: - | R21: - | S21: - | T21: - | U21: - | V21: - | W21: - | X21: - | Y21: - | Z21: =IF(X21="-","",IF(X21="Sliding",Y21,"")) | AA21: =IF(X21="-","",IF(X21="Toppling",Y21,"")) | AB21: =IF(X21="invalid","Invalid",IF(Z21="",AA21,Z21))
A22: 20 | B22: 36 | C22: 57 | D22: 79 | E22: 235 | F22: 31 | G22: 37 | H22: FALSE | I22: FALSE | J22: FALSE | K22: TRUE | L22: - | M22: - | N22: - | O22: - | P22: - | Q22: - | R22: - | S22: - | T22: - | U22: - | V22: - | W22: - | X22: - | Y22: - | Z22: =IF(X22="-","",IF(X22="Sliding",Y22,"")) | AA22: =IF(X22="-","",IF(X22="Toppling",Y22,"")) | AB22: =IF(X22="invalid","Invalid",IF(Z22="",AA22,Z22))
A23: 21 | B23: 25 | C23: 51 | D23: 68 | E23: 221 | F23: 31 | G23: 36 | H23: TRUE | I23: FALSE | J23: FALSE | K23: FALSE | L23: 8 | M23: 2 | N23: Stable | O23: 0 | P23: 69.617441 | Q23: 33.715115 | R23: 384.10619 | S23: 315.1382 | T23: 1.21885 | U23: 90.794696 | V23: 4.5373008 | W23: - | X23: Sliding | Y23: 1.21885 | Z23: =IF(X23="-","",IF(X23="Sliding",Y23,"")) -> 1.21885 | AA23: =IF(X23="-","",IF(X23="Toppling",Y23,"")) | AB23: =IF(X23="invalid","Invalid",IF(Z23="",AA23,Z23)) -> 1.21885
A24: 22 | B24: 36 | C24: 66 | D24: 64 | E24: 221 | F24: 32 | G24: 35 | H24: FALSE | I24: FALSE | J24: FALSE | K24: TRUE | L24: - | M24: - | N24: - | O24: - | P24: - | Q24: - | R24: - | S24: - | T24: - | U24: - | V24: - | W24: - | X24: - | Y24: - | Z24: =IF(X24="-","",IF(X24="Sliding",Y24,"")) | AA24: =IF(X24="-","",IF(X24="Toppling",Y24,"")) | AB24: =IF(X24="invalid","Invalid",IF(Z24="",AA24,Z24))
A25: 23 | B25: 27 | C25: 39 | D25: 67 | E25: 228 | F25: 33 | G25: 34 | H25: TRUE | I25: FALSE | J25: FALSE | K25: FALSE | L25: 9 | M25: 0 | N25: Sliding | O25: 2.5477296 | P25: 51.372046 | Q25: 28.825745 | R25: 33.148536 | S25: 28.825745 | T25: 1.1499629 | U25: 60.417557 | V25: 8.637874 | W25: 6.9944938 | X25: Sliding | Y25: 1.1499629 | Z25: =IF(X25="-","",IF(X25="Sliding",Y25,"")) -> 1.1499629 | AA25: =IF(X25="-","",IF(X25="Toppling",Y25,"")) | AB25: =IF(X25="invalid","Invalid",IF(Z25="",AA25,Z25)) -> 1.1499629
A26: 24 | B26: 32 | C26: 62 | D26: 65 | E26: 240 | F26: 33 | G26: 35 | H26: TRUE | I26: FALSE | J26: FALSE | K26: FALSE | L26: 8 | M26: 0 | N26: Sliding | O26: 30.999602 | P26: 63.252746 | Q26: 63.211651 | R26: 41.357256 | S26: 63.211651 | T26: 0.65426634 | U26: 103.2019 | V26: 71.598645 | W26: 1.4413946 | X26: Sliding | Y26: 0.65426634 | Z26: =IF(X26="-","",IF(X26="Sliding",Y26,"")) -> 0.65426634 | AA26: =IF(X26="-","",IF(X26="Toppling",Y26,"")) | AB26: =IF(X26="invalid","Invalid",IF(Z26="",AA26,Z26)) -> 0.65426634
A27: 25 | B27: 25 | C27: 48 | D27: 66 | E27: 224 | F27: 32 | G27: 37 | H27: TRUE | I27: FALSE | J27: FALSE | K27: FALSE | L27: 9 | M27: 0 | N27: Toppling | O27: 77.698749 | P27: 155.05901 | Q27: 126.66469 | R27: 96.479399 | S27: 126.66469 | T27: 0.76169137 | U27: 323.22892 | V27: 240.84429 | W27: 1.3420659 | X27: Sliding | Y27: 0.76169137 | Z27: =IF(X27="-","",IF(X27="Sliding",Y27,"")) -> 0.76169137 | AA27: =IF(X27="-","",IF(X27="Toppling",Y27,"")) | AB27: =IF(X27="invalid","Invalid",IF(Z27="",AA27,Z27)) -> 0.76169137
A28: 26 | B28: 31 | C28: 37 | D28: 70 | E28: 216 | F28: 35 | G28: 35 | H28: TRUE | I28: FALSE | J28: FALSE | K28: FALSE | L28: 7 | M28: 1 | N28: Stable | O28: 0 | P28: 76.92174 | Q28: 49.444001 | R28: 221.24544 | S28: 202.68377 | T28: 1.0915794 | U28: 119.13012 | V28: 6.4854011 | W28: - | X28: Sliding | Y28: 1.0915794 | Z28: =IF(X28="-","",IF(X28="Sliding",Y28,"")) -> 1.0915794 | AA28: =IF(X28="-","",IF(X28="Toppling",Y28,"")) | AB28: =IF(X28="invalid","Invalid",IF(Z28="",AA28,Z28)) -> 1.0915794
A29: 27 | B29: 33 | C29: 30 | D29: 78 | E29: 238 | F29: 35 | G29: 35 | H29: FALSE | I29: FALSE | J29: TRUE | K29: FALSE | L29: - | M29: - | N29: - | O29: - | P29: - | Q29: - | R29: - | S29: - | T29: - | U29: - | V29: - | W29: - | X29: - | Y29: - | Z29: =IF(X29="-","",IF(X29="Sliding",Y29,"")) | AA29: =IF(X29="-","",IF(X29="Toppling",Y29,"")) | AB29: =IF(X29="invalid","Invalid",IF(Z29="",AA29,Z29))
A30: 28 | B30: 30 | C30: 55 | D30: 77 | E30: 225 | F30: 33 | G30: 38 | H30: TRUE | I30: FALSE | J30: FALSE | K30: FALSE | L30: 7 | M30: 6 | N30: Stable | O30: 0 | P30: 81.654972 | Q30: 50.779139 | R30: 1179.5919 | S30: 1080.6706 | T30: 1.091537 | U30: 126.55754 | V30: 7.0782998 | W30: - | X30: Sliding | Y30: 1.091537 | Z30: =IF(X30="-","",IF(X30="Sliding",Y30,"")) -> 1.091537 | AA30: =IF(X30="-","",IF(X30="Toppling",Y30,"")) | AB30: =IF(X30="invalid","Invalid",IF(Z30="",AA30,Z30)) -> 1.091537
A31: 29 | B31: 25 | C31: 31 | D31: 57 | E31: 214 | F31: 37 | G31: 34 | H31: FALSE | I31: FALSE | J31: FALSE | K31: FALSE | L31: - | M31: - | N31: - | O31: - | P31: - | Q31: - | R31: - | S31: - | T31: - | U31: - | V31: - | W31: - | X31: - | Y31: - | Z31: =IF(X31="-","",IF(X31="Sliding",Y31,"")) | AA31: =IF(X31="-","",IF(X31="Toppling",Y31,"")) | AB31: =IF(X31="invalid","Invalid",IF(Z31="",AA31,Z31))
A32: 30 | B32: 35 | C32: 60 | D32: 78 | E32: 218 | F32: 31 | G32: 35 | H32: FALSE | I32: FALSE | J32: FALSE | K32: TRUE | L32: - | M32: - | N32: - | O32: - | P32: - | Q32: - | R32: - | S32: - | T32: - | U32: - | V32: - | W32: - | X32: - | Y32: - | Z32: =IF(X32="-","",IF(X32="Sliding",Y32,"")) | AA32: =IF(X32="-","",IF(X32="Toppling",Y32,"")) | AB32: =IF(X32="invalid","Invalid",IF(Z32="",AA32,Z32))
A33: 31 | B33: 39 | C33: 62 | D33: 69 | E33: 218 | F33: 31 | G33: 39 | H33: FALSE | I33: FALSE | J33: FALSE | K33: TRUE | L33: - | M33: - | N33: - | O33: - | P33: - | Q33: - | R33: - | S33: - | T33: - | U33: - | V33: - | W33: - | X33: - | Y33: - | Z33: =IF(X33="-","",IF(X33="Sliding",Y33,"")) | AA33: =IF(X33="-","",IF(X33="Toppling",Y33,"")) | AB33: =IF(X33="invalid","Invalid",IF(Z33="",AA33,Z33))
A34: 32 | B34: 30 | C34: 61 | D34: 62 | E34: 238 | F34: 37 | G34: 36 | H34: TRUE | I34: FALSE | J34: FALSE | K34: FALSE | L34: 8 | M34: 0 | N34: Toppling | O34: 73.720522 | P34: 127.97192 | Q34: 124.55939 | R34: 96.127234 | S34: 124.55939 | T34: 0.77173813 | U34: 276.0537 | V34: 201.20941 | W34: 1.3719721 | X34: Sliding | Y34: 0.77173813 | Z34: =IF(X34="-","",IF(X34="Sliding",Y34,"")) -> 0.77173813 | AA34: =IF(X34="-","",IF(X34="Toppling",Y34,"")) | AB34: =IF(X34="invalid","Invalid",IF(Z34="",AA34,Z34)) -> 0.77173813
A35: 33 | B35: 32 | C35: 39 | D35: 68 | E35: 224 | F35: 29 | G35: 38 | H35: FALSE | I35: FALSE | J35: FALSE | K35: TRUE | L35: - | M35: - | N35: - | O35: - | P35: - | Q35: - | R35: - | S35: - | T35: - | U35: - | V35: - | W35: - | X35: - | Y35: - | Z35: =IF(X35="-","",IF(X35="Sliding",Y35,"")) | AA35: =IF(X35="-","",IF(X35="Toppling",Y35,"")) | AB35: =IF(X35="invalid","Invalid",IF(Z35="",AA35,Z35))
A36: 34 | B36: 38 | C36: 47 | D36: 66 | E36: 217 | F36: 36 | G36: 38 | H36: FALSE | I36: FALSE | J36: FALSE | K36: TRUE | L36: - | M36: - | N36: - | O36: - | P36: - | Q36: - | R36: - | S36: - | T36: - | U36: - | V36: - | W36: - | X36: - | Y36: - | Z36: =IF(X36="-","",IF(X36="Sliding",Y36,"")) | AA36: =IF(X36="-","",IF(X36="Toppling",Y36,"")) | AB36: =IF(X36="invalid","Invalid",IF(Z36="",AA36,Z36))
A37: 35 | B37: 21 | C37: 43 | D37: 73 | E37: 228 | F37: 34 | G37: 40 | H37: TRUE | I37: FALSE | J37: FALSE | K37: FALSE | L37: 9 | M37: 2 | N37: Stable | O37: 0 | P37: 130.85894 | Q37: 52.906444 | R37: 603.19655 | S37: 362.32768 | T37: 1.6647819 | U37: 218.55818 | V37: 10.746054 | W37: - | X37: Sliding | Y37: 1.6647819 | Z37: =IF(X37="-","",IF(X37="Sliding",Y37,"")) -> 1.6647819 | AA37: =IF(X37="-","",IF(X37="Toppling",Y37,"")) | AB37: =IF(X37="invalid","Invalid",IF(Z37="",AA37,Z37)) -> 1.6647819
A38: 36 | B38: 24 | C38: 46 | D38: 71 | E38: 234 | F38: 35 | G38: 33 | H38: TRUE | I38: FALSE | J38: FALSE | K38: FALSE | L38: 9 | M38: 0 | N38: Toppling | O38: 13.141896 | P38: 109.95035 | Q38: 60.899688 | R38: 77.367079 | S38: 60.899688 | T38: 1.2704019 | U38: 181.96424 | V38: 53.527985 | W38: 3.3994225 | X38: Sliding | Y38: 1.2704019 | Z38: =IF(X38="-","",IF(X38="Sliding",Y38,"")) -> 1.2704019 | AA38: =IF(X38="-","",IF(X38="Toppling",Y38,"")) | AB38: =IF(X38="invalid","Invalid",IF(Z38="",AA38,Z38)) -> 1.2704019
A39: 37 | B39: 33 | C39: 50 | D39: 74 | E39: 227 | F39: 34 | G39: 32 | H39: TRUE | I39: FALSE | J39: FALSE | K39: FALSE | L39: 7 | M39: 6 | N39: Stable | O39: 0 | P39: 59.230239 | Q39: 40.163136 | R39: 977.33173 | S39: 943.3679 | T39: 1.0360027 | U39: 82.569445 | V39: 4.6792205 | W39: - | X39: Sliding | Y39: 1.0360027 | Z39: =IF(X39="-","",IF(X39="Sliding",Y39,"")) -> 1.0360027 | AA39: =IF(X39="-","",IF(X39="Toppling",Y39,"")) | AB39: =IF(X39="invalid","Invalid",IF(Z39="",AA39,Z39)) -> 1.0360027
A40: 38 | B40: 32 | C40: 44 | D40: 70 | E40: 231 | F40: 35 | G40: 36 | H40: TRUE | I40: FALSE | J40: FALSE | K40: FALSE | L40: 7 | M40: 2 | N40: Stable | O40: 0 | P40: 89.723383 | Q40: 59.011648 | R40: 383.06691 | S40: 351.44395 | T40: 1.0899801 | U40: 152.23131 | V40: 8.3055175 | W40: - | X40: Sliding | Y40: 1.0899801 | Z40: =IF(X40="-","",IF(X40="Sliding",Y40,"")) -> 1.0899801 | AA40: =IF(X40="-","",IF(X40="Toppling",Y40,"")) | AB40: =IF(X40="invalid","Invalid",IF(Z40="",AA40,Z40)) -> 1.0899801
...

Sheet Analysis Details 3
A1: Results of Trial # | C1: 1
A2: Total Blocks = | B2: 11
A3: Slope Height, H = | B3: 15 | C3: m
A4: Slope Angle, yS = | B4: 70 | C4: °
A5: Top Angle, yts= | B5: 2.5 | C5: °
A6: Dip of Set A, ya = | B6: 21.214362 | C6: °
A7: Dip of Set B, yb = | B7: 68.366004 | C7: °
A8: Unit Wt. Rock, grock = | B8: 26 | C8: kN/m3
A9: Unit Wt. Water, gwater = | B9: 9.81 | C9: kN/m3
A10: Seismic Coefficient = | B10: 0 | C10: g
A11: Pore Pressure = | B11: 0.1
A12: Toe Block Support = | B12: 0 | C12: kN
A13: Blocks Bolted Together = | B13: No
A14: Overall Slope Geometry
B16: x | C16: y
A17: Left Limit of Slope | B17: -10 | C17: 0
A18: Slope Toe | B18: 0 | C18: 0
A19: Slope Crest | B19: 5.4595535 | C19: 15
A20: Right Limit of Slope | B20: 44.103129 | C20: 16.687215
A21: Block | B21: Coordinates | D21: Water Table | F21: Centre of Mass | H21: Wn | I21: K | J21: V1 | K21: V2 | L21: V3 | M21: y1 | N21: y2 | O21: y3 | P21: yk | Q21: xw | R21: Sb | S21: Mn | T21: Ln | U21: fa | V21: fb | W21: Pn | X21: Pn-1:T | Y21: Pn-1:S | Z21: Pn-1 | AA21: Rn | AB21: Sn | AC21: Sliding | AD21: Mode
B22: x | C22: y | D22: x | E22: y | F22: x | G22: y | H22: (kN) | I22: (kN) | J22: (kN) | K22: (kN) | L22: (kN) | M22: (m) | N22: (m) | O22: (m) | P22: (m) | Q22: (m) | R22: (m) | S22: (m) | T22: (m) | U22: (°) | V22: (°) | W22: (kN) | X22: (kN) | Y22: (kN) | Z22: (kN) | AA22: (kN) | AB22: (kN)
A23: Block 1 | B23: 0 | C23: 0 | D23: 0 | E23: 0 | F23: 1.2143246 | G23: 1.490593 | H23: 93.292128 | I23: 0 | J23: 0.34439543 | K23: 3.2721165 | L23: 0 | M23: 0.076580754 | N23: 1.6783761 | O23: 0 | P23: 1.490593 | Q23: 1.2143246 | R23: 2.5174967 | S23: 2.8321383 | T23: 0 | U23: 33.374028 | V23: 33.052294 | W23: 84.863864 | X23: 0 | Y23: 0 | Z23: 0 | AA23: 139.5419 | AB23: 118.56006 | AC23: FALSE | AD23: See Analysis Details 2
B24: 0 | C24: 0 | D24: 2.2418628 | E24: 1.175979
B25: 2.3469567 | C25: 0.9110014
B26: 1.296017 | C26: 3.5607775
A27: Block 2 | B27: 1.296017 | C27: 3.5607775 | D27: 2.2418628 | E27: 1.175979 | F27: 2.8258494 | G27: 3.8355061 | H27: 268.9215 | I27: 0 | J27: 1.2208406 | K27: 4.5177187 | L27: 0 | M27: 0.15919074 | N27: 2.0757964 | O27: 0 | P27: 2.4311739 | Q27: 0.67455478 | R27: 2.6911121 | S27: 5.3473138 | T27: 2.3198613 | U27: 33.374028 | V27: 33.052294 | W27: 102.52583 | X27: 84.863864 | Y27: -10.76042 | Z27: 84.863864 | AA27: 257.81055 | AB27: 116.10959 | AC27: FALSE | AD27: Toppling
B28: 2.1512946 | C28: 1.4043322 | D28: 4.4622364 | E28: 2.8770554
B29: 4.6601057 | C29: 2.3781594
B30: 2.681412 | C30: 7.3671188
A31: Block 3 | B31: 2.681412 | C31: 7.3671188 | D31: 4.4622364 | E31: 2.8770554 | F31: 4.4895094 | G31: 6.3996535 | H31: 383.6863 | I31: 0 | J31: 2.3177897 | K31: 6.3970722 | L31: 0 | M31: 0.22849782 | N31: 1.8258003 | O31: 0 | P31: 3.3193485 | Q31: 0.10788474 | R31: 2.4581513 | S31: 7.3770453 | T31: 4.6116696 | U31: 33.374028 | V31: 33.052294 | W31: 86.888576 | X31: 102.52583 | Y31: -73.780388 | Z31: 102.52583 | AA31: 341.01547 | AB31: 125.59547 | AC31: FALSE | AD31: Toppling
B32: 4.3816246 | C32: 3.080305 | D32: 6.4006183 | E32: 4.6572438
B33: 6.6732561 | C33: 3.9698312
B34: 3.9468777 | C34: 10.843957
A35: Block 4 | B35: 3.9468777 | C35: 10.843957 | D35: 6.4006183 | E35: 4.6572438 | F35: 6.2211729 | G35: 8.9629418 | H35: 576.30593 | I35: 0 | J35: 4.0652743 | K35: 13.254081 | L35: 0.047789656 | M35: 0.30684621 | N35: 1.6978938 | O35: 0.035395638 | P35: 4.4044049 | Q35: -0.218594 | R35: 2.6777372 | S35: 9.7741371 | T35: 6.7617311 | U35: 33.374028 | V35: 33.052294 | W35: 54.507697 | X35: 86.888576 | Y35: -181.59636 | Z35: 86.888576 | AA35: 502.7198 | AB35: 180.33275 | AC35: FALSE | AD35: Toppling
B36: 6.4397669 | C36: 4.5585369 | D36: 8.5750369 | E36: 6.4379099
B37: 8.9361091 | C37: 5.5275242
B38: 5.3253872 | C38: 14.631381
A39: Block 5 | B39: 5.3253872 | C39: 14.631381 | D39: 8.5750369 | E39: 6.4379099 | F39: 8.1423311 | G39: 10.757832 | H39: 575.15971 | I39: 0 | J39: 3.2700857 | K39: 14.111449 | L39: 0.69485366 | M39: 0.2751306 | N39: 1.3541834 | O39: 0.13496758 | P39: 4.696303 | Q39: -0.5819838 | R39: 2.4116893 | S39: 8.7661602 | T39: 9.219277 | U39: 33.374028 | V39: 33.052294 | W39: 20.546811 | X39: 54.507697 | Y39: -216.59216 | Z39: 54.507697 | AA39: 499.74366 | AB39: 176.90333 | AC39: FALSE | AD39: Toppling
B40: 8.7243149 | C40: 6.0615294 | D40: 10.648793 | E40: 7.7507497
B41: 10.972632 | C41: 6.9342424
...
